Workbook

Sheet FMC_Setup_Sheet
A1: Definition | B1: FMC Pin Identifier | C1: Pin Alias | D1: Pin Direction | E1: HPC or LPC | F1: LPC | W1: Input
A2: User Clock Bidirectional | B2: CLK2_BIDIR_P | C2: Tim_P | D2: Input | E2: 1 | F2: 0 | W2: Output
A3: User Clock Bidirectional | B3: CLK2_BIDIR_N | C3: Tim_N | D3: Output | E3: 1 | F3: 0
A4: Differential Pair (User Defined) | B4: HA02_P | C4: Sally_P | D4: Input | E4: 1 | F4: 0
A5: Differential Pair (User Defined) | B5: HA02_N | C5: Sally_N | D5: Output | E5: 1 | F5: 0
A6: Differential Pair (User Defined) | B6: HA06_P | D6: Input | E6: 1 | F6: 0
A7: Differential Pair (User Defined) | B7: HA06_N | D7: Input | E7: 1 | F7: 0
A8: Differential Pair (User Defined) | B8: HA10_P | D8: Input | E8: 1 | F8: 0
A9: Differential Pair (User Defined) | B9: HA10_N | D9: Input | E9: 1 | F9: 0
A10: Differential Pair (User Defined, Clock Capable) | B10: HA17_P_CC | D10: Input | E10: 1 | F10: 0
A11: Differential Pair (User Defined, Clock Capable) | B11: HA17_N_CC | D11: Input | E11: 1 | F11: 0
A12: Differential Pair (User Defined) | B12: HA21_P | D12: Input | E12: 1 | F12: 0
A13: Differential Pair (User Defined) | B13: HA21_N | D13: Input | E13: 1 | F13: 0
A14: Differential Pair (User Defined) | B14: HA23_P | D14: Input | E14: 1 | F14: 0
A15: Differential Pair (User Defined) | B15: HA23_N | D15: Input | E15: 1 | F15: 0
A16: Differential Pair (User Defined, Clock Capable) | B16: HB00_P_CC | D16: Input | E16: 1 | F16: 0
A17: Differential Pair (User Defined, Clock Capable) | B17: HB00_N_CC | D17: Input | E17: 1 | F17: 0
... A49: Differential Pair (User Defined) | B49: HB18_N | D49: Input | E49: 1 | F49: 0
A50: User Clock Mezzanine to Carrier | B50: CLK0_M2C_P | C50: George_P | D50: Input | E50: 2 | F50: 2
A51: User Clock Mezzanine to Carrier | B51: CLK0_M2C_N | C51: George_N | D51: Output | E51: 2 | F51: 2
A52: Differential Pair (User Defined) | B52: LA02_P | D52: Input | E52: 2 | F52: 2
A53: Differential Pair (User Defined) | B53: LA02_N | D53: Input | E53: 2 | F53: 2
A54: Differential Pair (User Defined) | B54: LA04_P | D54: Input | E54: 2 | F54: 2
A55: Differential Pair (User Defined) | B55: LA04_N | D55: Input | E55: 2 | F55: 2
A56: Differential Pair (User Defined) | B56: LA07_P | D56: Input | E56: 2 | F56: 2
A57: Differential Pair (User Defined) | B57: LA07_N | D57: Input | E57: 2 | F57: 2
A58: Differential Pair (User Defined) | B58: LA11_P | D58: Input | E58: 2 | F58: 2
A59: Differential Pair (User Defined) | B59: LA11_N | D59: Input | E59: 2 | F59: 2
A60: Differential Pair (User Defined) | B60: LA15_P | D60: Input | E60: 2 | F60: 2
A61: Differential Pair (User Defined) | B61: LA15_N | D61: Input | E61: 2 | F61: 2
A62: Differential Pair (User Defined) | B62: LA19_P | C62: Ruth_P | D62: Input | E62: 2 | F62: 2
A63: Differential Pair (User Defined) | B63: LA19_N | C63: Ruth_N | D63: Output | E63: 2 | F63: 2
A64: Differential Pair (User Defined) | B64: LA21_P | D64: Input | E64: 2 | F64: 2
A65: Differential Pair (User Defined) | B65: LA21_N | D65: Input | E65: 2 | F65: 2
A66: Differential Pair (User Defined) | B66: LA24_P | D66: Input | E66: 2 | F66: 2
A67: Differential Pair (User Defined) | B67: LA24_N | D67: Input | E67: 2 | F67: 2
A68: Differential Pair (User Defined) | B68: LA28_P | D68: Input | E68: 2 | F68: 2
A69: Differential Pair (User Defined) | B69: LA28_N | D69: Input | E69: 2 | F69: 2
A70: Differential Pair (User Defined) | B70: LA30_P | D70: Input | E70: 2 | F70: 2
A71: Differential Pair (User Defined) | B71: LA30_N | D71: Input | E71: 2 | F71: 2
...

Sheet FMC_Export_Sheet
A1: Name | B1: Alias | C1: Direction | D1: HPC or LPC
A2: =FMC_Setup_Sheet!B2 -> CLK2_BIDIR_P | B2: =FMC_Setup_Sheet!C2 -> Tim_P | C2: =FMC_Setup_Sheet!D2 -> Input | D2: =FMC_Setup_Sheet!E2 -> 1
A3: =FMC_Setup_Sheet!B3 -> CLK2_BIDIR_N | B3: =FMC_Setup_Sheet!C3 -> Tim_N | C3: =FMC_Setup_Sheet!D3 -> Output | D3: =FMC_Setup_Sheet!E3 -> 1
A4: =FMC_Setup_Sheet!B4 -> HA02_P | B4: =FMC_Setup_Sheet!C4 -> Sally_P | C4: =FMC_Setup_Sheet!D4 -> Input | D4: =FMC_Setup_Sheet!E4 -> 1
A5: =FMC_Setup_Sheet!B5 -> HA02_N | B5: =FMC_Setup_Sheet!C5 -> Sally_N | C5: =FMC_Setup_Sheet!D5 -> Output | D5: =FMC_Setup_Sheet!E5 -> 1
A6: =FMC_Setup_Sheet!B6 -> HA06_P | B6: =FMC_Setup_Sheet!C6 -> 0 | C6: =FMC_Setup_Sheet!D6 -> Input | D6: =FMC_Setup_Sheet!E6 -> 1
A7: =FMC_Setup_Sheet!B7 -> HA06_N | B7: =FMC_Setup_Sheet!C7 -> 0 | C7: =FMC_Setup_Sheet!D7 -> Input | D7: =FMC_Setup_Sheet!E7 -> 1
A8: =FMC_Setup_Sheet!B8 -> HA10_P | B8: =FMC_Setup_Sheet!C8 -> 0 | C8: =FMC_Setup_Sheet!D8 -> Input | D8: =FMC_Setup_Sheet!E8 -> 1
A9: =FMC_Setup_Sheet!B9 -> HA10_N | B9: =FMC_Setup_Sheet!C9 -> 0 | C9: =FMC_Setup_Sheet!D9 -> Input | D9: =FMC_Setup_Sheet!E9 -> 1
A10: =FMC_Setup_Sheet!B10 -> HA17_P_CC | B10: =FMC_Setup_Sheet!C10 -> 0 | C10: =FMC_Setup_Sheet!D10 -> Input | D10: =FMC_Setup_Sheet!E10 -> 1
A11: =FMC_Setup_Sheet!B11 -> HA17_N_CC | B11: =FMC_Setup_Sheet!C11 -> 0 | C11: =FMC_Setup_Sheet!D11 -> Input | D11: =FMC_Setup_Sheet!E11 -> 1
A12: =FMC_Setup_Sheet!B12 -> HA21_P | B12: =FMC_Setup_Sheet!C12 -> 0 | C12: =FMC_Setup_Sheet!D12 -> Input | D12: =FMC_Setup_Sheet!E12 -> 1
A13: =FMC_Setup_Sheet!B13 -> HA21_N | B13: =FMC_Setup_Sheet!C13 -> 0 | C13: =FMC_Setup_Sheet!D13 -> Input | D13: =FMC_Setup_Sheet!E13 -> 1
... A214: =FMC_Setup_Sheet!B214 -> DP5_C2M_N | B214: =FMC_Setup_Sheet!C214 -> 0 | C214: =FMC_Setup_Sheet!D214 -> Input | D214: =FMC_Setup_Sheet!E214 -> 1
