Workbook

Sheet Table
E1: Address
A2: Prefix | B2: Suffix | C2: Num | D2: Reg | E2: Dec | F2: Hex | G2: Bin | H2: Description | I2: R/W | J2: Format | K2: Scale
A3: HTR | B3: CNTLMD | C3: 0 | D3: =E3/2 -> 0 | E3: =C3*2 -> 0 | F3: =DEC2HEX(E3,4) -> 0000 | G3: =DEC2BIN(E3,9) -> 000000000 | H3: Auto Manual Mode Select | I3: RW | J3: U16 | K3: CSX
A4: HTR | B4: LCLPWR | C4: =C3+1 -> 1 | D4: =E4/2 -> 1 | E4: =IF((OR(J3="U16",J3="S16")),E3+2,E3+4) -> 2 | F4: =DEC2HEX(E4,4) -> 0002 | G4: =DEC2BIN(E4,9) -> 000000010 | H4: Local Heat Setpoint | I4: RW | J4: U16 | K4: CSX
A5: HTR | B5: IRB | C5: =C4+1 -> 2 | D5: =E5/2 -> 2 | E5: =IF((OR(J4="U16",J4="S16")),E4+2,E4+4) -> 4 | F5: =DEC2HEX(E5,4) -> 0004 | G5: =DEC2BIN(E5,9) -> 000000100 | H5: Current Readback | I5: RO | J5: U16 | K5: CSX
A6: HTR | B6: VRB | C6: =C5+1 -> 3 | D6: =E6/2 -> 3 | E6: =IF((OR(J5="U16",J5="S16")),E5+2,E5+4) -> 6 | F6: =DEC2HEX(E6,4) -> 0006 | G6: =DEC2BIN(E6,9) -> 000000110 | H6: Voltage Readback | I6: RO | J6: U16 | K6: CSX
A7: HTR | B7: FVER | C7: =C6+1 -> 4 | D7: =E7/2 -> 4 | E7: =IF((OR(J6="U16",J6="S16")),E6+2,E6+4) -> 8 | F7: =DEC2HEX(E7,4) -> 0008 | G7: =DEC2BIN(E7,9) -> 000001000 | H7: Firmware Version | I7: RO | J7: U16 | K7: CSX
A8: HTR | B8: HVER | C8: =C7+1 -> 5 | D8: =E8/2 -> 5 | E8: =IF((OR(J7="U16",J7="S16")),E7+2,E7+4) -> 10 | F8: =DEC2HEX(E8,4) -> 000A | G8: =DEC2BIN(E8,9) -> 000001010 | H8: HRT Version | I8: RO | J8: U16 | K8: CSX
A9: HTR | B9: DAC | C9: =C8+1 -> 6 | D9: =E9/2 -> 6 | E9: =IF((OR(J8="U16",J8="S16")),E8+2,E8+4) -> 12 | F9: =DEC2HEX(E9,4) -> 000C | G9: =DEC2BIN(E9,9) -> 000001100 | H9: DAC Setpoint | I9: RW | J9: U16 | K9: CSX
A10: HTR | B10: RSTR | C10: =C9+1 -> 7 | D10: =E10/2 -> 7 | E10: =IF((OR(J9="U16",J9="S16")),E9+2,E9+4) -> 14 | F10: =DEC2HEX(E10,4) -> 000E | G10: =DEC2BIN(E10,9) -> 000001110 | H10: Restore Status | I10: RW | J10: U16 | K10: CSX
A11: HTR | B11: HB | C11: =C10+1 -> 8 | D11: =E11/2 -> 8 | E11: =IF((OR(J10="U16",J10="S16")),E10+2,E10+4) -> 16 | F11: =DEC2HEX(E11,4) -> 0010 | G11: =DEC2BIN(E11,9) -> 000010000 | H11: Heartbeat | I11: RO | J11: U16 | K11: CSX
C12: =C11+1 -> 9 | D12: =E12/2 -> 9 | E12: =IF((OR(J11="U16",J11="S16")),E11+2,E11+4) -> 18 | F12: =DEC2HEX(E12,4) -> 0012 | G12: =DEC2BIN(E12,9) -> 000010010 | I12: RO | J12: S16 | K12: CSX
C13: =C12+1 -> 10 | D13: =E13/2 -> 10 | E13: =IF((OR(J12="U16",J12="S16")),E12+2,E12+4) -> 20 | F13: =DEC2HEX(E13,4) -> 0014 | G13: =DEC2BIN(E13,9) -> 000010100 | I13: RO | J13: S16 | K13: CSX
C14: =C13+1 -> 11 | D14: =E14/2 -> 11 | E14: =IF((OR(J13="U16",J13="S16")),E13+2,E13+4) -> 22 | F14: =DEC2HEX(E14,4) -> 0016 | G14: =DEC2BIN(E14,9) -> 000010110 | I14: RO | J14: S16 | K14: CSX
C15: =C14+1 -> 12 | D15: =E15/2 -> 12 | E15: =IF((OR(J14="U16",J14="S16")),E14+2,E14+4) -> 24 | F15: =DEC2HEX(E15,4) -> 0018 | G15: =DEC2BIN(E15,9) -> 000011000 | I15: RO | J15: S16 | K15: CSX
C16: =C15+1 -> 13 | D16: =E16/2 -> 13 | E16: =IF((OR(J15="U16",J15="S16")),E15+2,E15+4) -> 26 | F16: =DEC2HEX(E16,4) -> 001A | G16: =DEC2BIN(E16,9) -> 000011010 | I16: RO | J16: S16 | K16: CSX
C17: =C16+1 -> 14 | D17: =E17/2 -> 14 | E17: =IF((OR(J16="U16",J16="S16")),E16+2,E16+4) -> 28 | F17: =DEC2HEX(E17,4) -> 001C | G17: =DEC2BIN(E17,9) -> 000011100 | I17: RO | J17: S16 | K17: CSX
C18: =C17+1 -> 15 | D18: =E18/2 -> 15 | E18: =IF((OR(J17="U16",J17="S16")),E17+2,E17+4) -> 30 | F18: =DEC2HEX(E18,4) -> 001E | G18: =DEC2BIN(E18,9) -> 000011110 | I18: RO | J18: S16 | K18: CSX
C19: =C18+1 -> 16 | D19: =E19/2 -> 16 | E19: =IF((OR(J18="U16",J18="S16")),E18+2,E18+4) -> 32 | F19: =DEC2HEX(E19,4) -> 0020 | G19: =DEC2BIN(E19,9) -> 000100000 | I19: RO | J19: S16 | K19: CSX
C20: =C19+1 -> 17 | D20: =E20/2 -> 17 | E20: =IF((OR(J19="U16",J19="S16")),E19+2,E19+4) -> 34 | F20: =DEC2HEX(E20,4) -> 0022 | G20: =DEC2BIN(E20,9) -> 000100010 | I20: RO | J20: S16 | K20: CSX
C21: =C20+1 -> 18 | D21: =E21/2 -> 18 | E21: =IF((OR(J20="U16",J20="S16")),E20+2,E20+4) -> 36 | F21: =DEC2HEX(E21,4) -> 0024 | G21: =DEC2BIN(E21,9) -> 000100100 | I21: RO | J21: S16 | K21: CSX
C22: =C21+1 -> 19 | D22: =E22/2 -> 19 | E22: =IF((OR(J21="U16",J21="S16")),E21+2,E21+4) -> 38 | F22: =DEC2HEX(E22,4) -> 0026 | G22: =DEC2BIN(E22,9) -> 000100110 | I22: RO | J22: S16 | K22: CSX
C23: =C22+1 -> 20 | D23: =E23/2 -> 20 | E23: =IF((OR(J22="U16",J22="S16")),E22+2,E22+4) -> 40 | F23: =DEC2HEX(E23,4) -> 0028 | G23: =DEC2BIN(E23,9) -> 000101000 | I23: RO | J23: S16 | K23: CSX
... C108: =C107+1 -> 105 | D108: =E108/2 -> 105 | E108: =IF((OR(J107="U16",J107="S16")),E107+2,E107+4) -> 210 | F108: =DEC2HEX(E108,4) -> 00D2 | G108: =DEC2BIN(E108,9) -> 011010010 | I108: RO | J108: U16 | K108: CXX

Sheet Software
A1: =CONCATENATE("{ """,Table!A3,""",",IF(LEN(Table!A3)=0," ",IF(LEN(Table!A3)=1," "," ")),"""",Table!B3,""",",IF(LEN(Table!B3)=0," ",IF(LEN(Table!B3)=1," ",IF(LEN(Table!B3)=2," ",IF(LEN(Table!B3)=3," ",IF(LEN(Table!B3)=4," ",IF(LEN(Table!B3)=5," "," ")))))),"0x",Table!F3,", ",Table!J3,",",IF(OR((Table!J3="U16"),(Table!J3="S16"))," "," "),Table!I3,", ",Table!K3,IF(Table!C3<10,", "" ",IF(Table!C3<100,", "" ",", """)),Table!C3," ",Table!H3,""" },") -> { "HTR", "CNTLMD", 0x0000, U16, RW, CSX, " 0 Auto Manual Mode Select" },
A2: =CONCATENATE("{ """,Table!A4,""",",IF(LEN(Table!A4)=0," ",IF(LEN(Table!A4)=1," "," ")),"""",Table!B4,""",",IF(LEN(Table!B4)=0," ",IF(LEN(Table!B4)=1," ",IF(LEN(Table!B4)=2," ",IF(LEN(Table!B4)=3," ",IF(LEN(Table!B4)=4," ",IF(LEN(Table!B4)=5," "," ")))))),"0x",Table!F4,", ",Table!J4,",",IF(OR((Table!J4="U16"),(Table!J4="S16"))," "," "),Table!I4,", ",Table!K4,IF(Table!C4<10,", "" ",IF(Table!C4<100,", "" ",", """)),Table!C4," ",Table!H4,""" },") -> { "HTR", "LCLPWR", 0x0002, U16, RW, CSX, " 1 Local Heat Setpoint" },
A3: =CONCATENATE("{ """,Table!A5,""",",IF(LEN(Table!A5)=0," ",IF(LEN(Table!A5)=1," "," ")),"""",Table!B5,""",",IF(LEN(Table!B5)=0," ",IF(LEN(Table!B5)=1," ",IF(LEN(Table!B5)=2," ",IF(LEN(Table!B5)=3," ",IF(LEN(Table!B5)=4," ",IF(LEN(Table!B5)=5," "," ")))))),"0x",Table!F5,", ",Table!J5,",",IF(OR((Table!J5="U16"),(Table!J5="S16"))," "," "),Table!I5,", ",Table!K5,IF(Table!C5<10,", "" ",IF(Table!C5<100,", "" ",", """)),Table!C5," ",Table!H5,""" },") -> { "HTR", "IRB", 0x0004, U16, RO, CSX, " 2 Current Readback" },
A4: =CONCATENATE("{ """,Table!A6,""",",IF(LEN(Table!A6)=0," ",IF(LEN(Table!A6)=1," "," ")),"""",Table!B6,""",",IF(LEN(Table!B6)=0," ",IF(LEN(Table!B6)=1," ",IF(LEN(Table!B6)=2," ",IF(LEN(Table!B6)=3," ",IF(LEN(Table!B6)=4," ",IF(LEN(Table!B6)=5," "," ")))))),"0x",Table!F6,", ",Table!J6,",",IF(OR((Table!J6="U16"),(Table!J6="S16"))," "," "),Table!I6,", ",Table!K6,IF(Table!C6<10,", "" ",IF(Table!C6<100,", "" ",", """)),Table!C6," ",Table!H6,""" },") -> { "HTR", "VRB", 0x0006, U16, RO, CSX, " 3 Voltage Readback" },
A5: =CONCATENATE("{ """,Table!A7,""",",IF(LEN(Table!A7)=0," ",IF(LEN(Table!A7)=1," "," ")),"""",Table!B7,""",",IF(LEN(Table!B7)=0," ",IF(LEN(Table!B7)=1," ",IF(LEN(Table!B7)=2," ",IF(LEN(Table!B7)=3," ",IF(LEN(Table!B7)=4," ",IF(LEN(Table!B7)=5," "," ")))))),"0x",Table!F7,", ",Table!J7,",",IF(OR((Table!J7="U16"),(Table!J7="S16"))," "," "),Table!I7,", ",Table!K7,IF(Table!C7<10,", "" ",IF(Table!C7<100,", "" ",", """)),Table!C7," ",Table!H7,""" },") -> { "HTR", "FVER", 0x0008, U16, RO, CSX, " 4 Firmware Version" },
A6: =CONCATENATE("{ """,Table!A8,""",",IF(LEN(Table!A8)=0," ",IF(LEN(Table!A8)=1," "," ")),"""",Table!B8,""",",IF(LEN(Table!B8)=0," ",IF(LEN(Table!B8)=1," ",IF(LEN(Table!B8)=2," ",IF(LEN(Table!B8)=3," ",IF(LEN(Table!B8)=4," ",IF(LEN(Table!B8)=5," "," ")))))),"0x",Table!F8,", ",Table!J8,",",IF(OR((Table!J8="U16"),(Table!J8="S16"))," "," "),Table!I8,", ",Table!K8,IF(Table!C8<10,", "" ",IF(Table!C8<100,", "" ",", """)),Table!C8," ",Table!H8,""" },") -> { "HTR", "HVER", 0x000A, U16, RO, CSX, " 5 HRT Version" },
A7: =CONCATENATE("{ """,Table!A9,""",",IF(LEN(Table!A9)=0," ",IF(LEN(Table!A9)=1," "," ")),"""",Table!B9,""",",IF(LEN(Table!B9)=0," ",IF(LEN(Table!B9)=1," ",IF(LEN(Table!B9)=2," ",IF(LEN(Table!B9)=3," ",IF(LEN(Table!B9)=4," ",IF(LEN(Table!B9)=5," "," ")))))),"0x",Table!F9,", ",Table!J9,",",IF(OR((Table!J9="U16"),(Table!J9="S16"))," "," "),Table!I9,", ",Table!K9,IF(Table!C9<10,", "" ",IF(Table!C9<100,", "" ",", """)),Table!C9," ",Table!H9,""" },") -> { "HTR", "DAC", 0x000C, U16, RW, CSX, " 6 DAC Setpoint" },
A8: =CONCATENATE("{ """,Table!A10,""",",IF(LEN(Table!A10)=0," ",IF(LEN(Table!A10)=1," "," ")),"""",Table!B10,""",",IF(LEN(Table!B10)=0," ",IF(LEN(Table!B10)=1," ",IF(LEN(Table!B10)=2," ",IF(LEN(Table!B10)=3," ",IF(LEN(Table!B10)=4," ",IF(LEN(Table!B10)=5," "," ")))))),"0x",Table!F10,", ",Table!J10,",",IF(OR((Table!J10="U16"),(Table!J10="S16"))," "," "),Table!I10,", ",Table!K10,IF(Table!C10<10,", "" ",IF(Table!C10<100,", "" ",", """)),Table!C10," ",Table!H10,""" },") -> { "HTR", "RSTR", 0x000E, U16, RW, CSX, " 7 Restore Status" },
A9: =CONCATENATE("{ """,Table!A11,""",",IF(LEN(Table!A11)=0," ",IF(LEN(Table!A11)=1," "," ")),"""",Table!B11,""",",IF(LEN(Table!B11)=0," ",IF(LEN(Table!B11)=1," ",IF(LEN(Table!B11)=2," ",IF(LEN(Table!B11)=3," ",IF(LEN(Table!B11)=4," ",IF(LEN(Table!B11)=5," "," ")))))),"0x",Table!F11,", ",Table!J11,",",IF(OR((Table!J11="U16"),(Table!J11="S16"))," "," "),Table!I11,", ",Table!K11,IF(Table!C11<10,", "" ",IF(Table!C11<100,", "" ",", """)),Table!C11," ",Table!H11,""" },") -> { "HTR", "HB", 0x0010, U16, RO, CSX, " 8 Heartbeat " },
A10: =CONCATENATE("{ """,Table!A12,""",",IF(LEN(Table!A12)=0," ",IF(LEN(Table!A12)=1," "," ")),"""",Table!B12,""",",IF(LEN(Table!B12)=0," ",IF(LEN(Table!B12)=1," ",IF(LEN(Table!B12)=2," ",IF(LEN(Table!B12)=3," ",IF(LEN(Table!B12)=4," ",IF(LEN(Table!B12)=5," "," ")))))),"0x",Table!F12,", ",Table!J12,",",IF(OR((Table!J12="U16"),(Table!J12="S16"))," "," "),Table!I12,", ",Table!K12,IF(Table!C12<10,", "" ",IF(Table!C12<100,", "" ",", """)),Table!C12," ",Table!H12,""" },") -> { "", "", 0x0012, S16, RO, CSX, " 9 " },
A11: =CONCATENATE("{ """,Table!A13,""",",IF(LEN(Table!A13)=0," ",IF(LEN(Table!A13)=1," "," ")),"""",Table!B13,""",",IF(LEN(Table!B13)=0," ",IF(LEN(Table!B13)=1," ",IF(LEN(Table!B13)=2," ",IF(LEN(Table!B13)=3," ",IF(LEN(Table!B13)=4," ",IF(LEN(Table!B13)=5," "," ")))))),"0x",Table!F13,", ",Table!J13,",",IF(OR((Table!J13="U16"),(Table!J13="S16"))," "," "),Table!I13,", ",Table!K13,IF(Table!C13<10,", "" ",IF(Table!C13<100,", "" ",", """)),Table!C13," ",Table!H13,""" },") -> { "", "", 0x0014, S16, RO, CSX, " 10 " },
A12: =CONCATENATE("{ """,Table!A14,""",",IF(LEN(Table!A14)=0," ",IF(LEN(Table!A14)=1," "," ")),"""",Table!B14,""",",IF(LEN(Table!B14)=0," ",IF(LEN(Table!B14)=1," ",IF(LEN(Table!B14)=2," ",IF(LEN(Table!B14)=3," ",IF(LEN(Table!B14)=4," ",IF(LEN(Table!B14)=5," "," ")))))),"0x",Table!F14,", ",Table!J14,",",IF(OR((Table!J14="U16"),(Table!J14="S16"))," "," "),Table!I14,", ",Table!K14,IF(Table!C14<10,", "" ",IF(Table!C14<100,", "" ",", """)),Table!C14," ",Table!H14,""" },") -> { "", "", 0x0016, S16, RO, CSX, " 11 " },
... A106: =CONCATENATE("{ """,Table!A108,""",",IF(LEN(Table!A108)=0," ",IF(LEN(Table!A108)=1," "," ")),"""",Table!B108,""",",IF(LEN(Table!B108)=0," ",IF(LEN(Table!B108)=1," ",IF(LEN(Table!B108)=2," ",IF(LEN(Table!B108)=3," ",IF(LEN(Table!B108)=4," ",IF(LEN(Table!B108)=5," "," ")))))),"0x",Table!F108,", ",Table!J108,",",IF(OR((Table!J108="U16"),(Table!J108="S16"))," "," "),Table!I108,", ",Table!K108,IF(Table!C108<10,", "" ",IF(Table!C108<100,", "" ",", """)),Table!C108," ",Table!H108,""" },") -> { "", "", 0x00D2, U16, RO, CXX, "105 " },

Sheet VHDL_HRT
A1: =IF(Table!I3="RO",CONCATENATE(" reg_ena","(",Table!D3,")"," <= '1';"," ","reg_d(",Table!D3,") <= x""FFFF"";"),CONCATENATE(" reg_ena","(",Table!D3,")"," <= '1' when (LOAD = '1') and (shrt_addr = x""",DEC2HEX(Table!D3,2),""")"," else '0';"," ","reg_d(",Table!D3,") <= DIN;")) -> reg_ena(0) <= '1' when (LOAD = '1') and (shrt_addr = x"00") else '0'; reg_d(0) <= DIN;
A2: =IF(Table!I4="RO",CONCATENATE(" reg_ena","(",Table!D4,")"," <= '1';"," ","reg_d(",Table!D4,") <= x""FFFF"";"),CONCATENATE(" reg_ena","(",Table!D4,")"," <= '1' when (LOAD = '1') and (shrt_addr = x""",DEC2HEX(Table!D4,2),""")"," else '0';"," ","reg_d(",Table!D4,") <= DIN;")) -> reg_ena(1) <= '1' when (LOAD = '1') and (shrt_addr = x"01") else '0'; reg_d(1) <= DIN;
A3: =IF(Table!I5="RO",CONCATENATE(" reg_ena","(",Table!D5,")"," <= '1';"," ","reg_d(",Table!D5,") <= x""FFFF"";"),CONCATENATE(" reg_ena","(",Table!D5,")"," <= '1' when (LOAD = '1') and (shrt_addr = x""",DEC2HEX(Table!D5,2),""")"," else '0';"," ","reg_d(",Table!D5,") <= DIN;")) -> reg_ena(2) <= '1'; reg_d(2) <= x"FFFF";
A4: =IF(Table!I6="RO",CONCATENATE(" reg_ena","(",Table!D6,")"," <= '1';"," ","reg_d(",Table!D6,") <= x""FFFF"";"),CONCATENATE(" reg_ena","(",Table!D6,")"," <= '1' when (LOAD = '1') and (shrt_addr = x""",DEC2HEX(Table!D6,2),""")"," else '0';"," ","reg_d(",Table!D6,") <= DIN;")) -> reg_ena(3) <= '1'; reg_d(3) <= x"FFFF";
A5: =IF(Table!I7="RO",CONCATENATE(" reg_ena","(",Table!D7,")"," <= '1';"," ","reg_d(",Table!D7,") <= x""FFFF"";"),CONCATENATE(" reg_ena","(",Table!D7,")"," <= '1' when (LOAD = '1') and (shrt_addr = x""",DEC2HEX(Table!D7,2),""")"," else '0';"," ","reg_d(",Table!D7,") <= DIN;")) -> reg_ena(4) <= '1'; reg_d(4) <= x"FFFF";
A6: =IF(Table!I8="RO",CONCATENATE(" reg_ena","(",Table!D8,")"," <= '1';"," ","reg_d(",Table!D8,") <= x""FFFF"";"),CONCATENATE(" reg_ena","(",Table!D8,")"," <= '1' when (LOAD = '1') and (shrt_addr = x""",DEC2HEX(Table!D8,2),""")"," else '0';"," ","reg_d(",Table!D8,") <= DIN;")) -> reg_ena(5) <= '1'; reg_d(5) <= x"FFFF";
A7: =IF(Table!I9="RO",CONCATENATE(" reg_ena","(",Table!D9,")"," <= '1';"," ","reg_d(",Table!D9,") <= x""FFFF"";"),CONCATENATE(" reg_ena","(",Table!D9,")"," <= '1' when (LOAD = '1') and (shrt_addr = x""",DEC2HEX(Table!D9,2),""")"," else '0';"," ","reg_d(",Table!D9,") <= DIN;")) -> reg_ena(6) <= '1' when (LOAD = '1') and (shrt_addr = x"06") else '0'; reg_d(6) <= DIN;
A8: =IF(Table!I10="RO",CONCATENATE(" reg_ena","(",Table!D10,")"," <= '1';"," ","reg_d(",Table!D10,") <= x""FFFF"";"),CONCATENATE(" reg_ena","(",Table!D10,")"," <= '1' when (LOAD = '1') and (shrt_addr = x""",DEC2HEX(Table!D10,2),""")"," else '0';"," ","reg_d(",Table!D10,") <= DIN;")) -> reg_ena(7) <= '1' when (LOAD = '1') and (shrt_addr = x"07") else '0'; reg_d(7) <= DIN;
A9: =IF(Table!I11="RO",CONCATENATE(" reg_ena","(",Table!D11,")"," <= '1';"," ","reg_d(",Table!D11,") <= x""FFFF"";"),CONCATENATE(" reg_ena","(",Table!D11,")"," <= '1' when (LOAD = '1') and (shrt_addr = x""",DEC2HEX(Table!D11,2),""")"," else '0';"," ","reg_d(",Table!D11,") <= DIN;")) -> reg_ena(8) <= '1'; reg_d(8) <= x"FFFF";
A10: =IF(Table!I12="RO",CONCATENATE(" reg_ena","(",Table!D12,")"," <= '1';"," ","reg_d(",Table!D12,") <= x""FFFF"";"),CONCATENATE(" reg_ena","(",Table!D12,")"," <= '1' when (LOAD = '1') and (shrt_addr = x""",DEC2HEX(Table!D12,2),""")"," else '0';"," ","reg_d(",Table!D12,") <= DIN;")) -> reg_ena(9) <= '1'; reg_d(9) <= x"FFFF";
A11: =IF(Table!I13="RO",CONCATENATE(" reg_ena","(",Table!D13,")"," <= '1';"," ","reg_d(",Table!D13,") <= x""FFFF"";"),CONCATENATE(" reg_ena","(",Table!D13,")"," <= '1' when (LOAD = '1') and (shrt_addr = x""",DEC2HEX(Table!D13,2),""")"," else '0';"," ","reg_d(",Table!D13,") <= DIN;")) -> reg_ena(10) <= '1'; reg_d(10) <= x"FFFF";
A12: =IF(Table!I14="RO",CONCATENATE(" reg_ena","(",Table!D14,")"," <= '1';"," ","reg_d(",Table!D14,") <= x""FFFF"";"),CONCATENATE(" reg_ena","(",Table!D14,")"," <= '1' when (LOAD = '1') and (shrt_addr = x""",DEC2HEX(Table!D14,2),""")"," else '0';"," ","reg_d(",Table!D14,") <= DIN;")) -> reg_ena(11) <= '1'; reg_d(11) <= x"FFFF";
... A106: =IF(Table!I108="RO",CONCATENATE(" reg_ena","(",Table!D108,")"," <= '1';"," ","reg_d(",Table!D108,") <= x""FFFF"";"),CONCATENATE(" reg_ena","(",Table!D108,")"," <= '1' when (LOAD = '1') and (shrt_addr = x""",DEC2HEX(Table!D108,2),""")"," else '0';"," ","reg_d(",Table!D108,") <= DIN;")) -> reg_ena(105) <= '1'; reg_d(105) <= x"FFFF";
A108: with shrt_addr select DOUT <=
A109: =CONCATENATE(" reg_q(",Table!D3,") when x""",DEC2HEX(Table!D3,2),"""",",") -> reg_q(0) when x"00",
A110: =CONCATENATE(" reg_q(",Table!D4,") when x""",DEC2HEX(Table!D4,2),"""",",") -> reg_q(1) when x"01",
A111: =CONCATENATE(" reg_q(",Table!D5,") when x""",DEC2HEX(Table!D5,2),"""",",") -> reg_q(2) when x"02",
A112: =CONCATENATE(" reg_q(",Table!D6,") when x""",DEC2HEX(Table!D6,2),"""",",") -> reg_q(3) when x"03",
A113: =CONCATENATE(" reg_q(",Table!D7,") when x""",DEC2HEX(Table!D7,2),"""",",") -> reg_q(4) when x"04",
A114: =CONCATENATE(" reg_q(",Table!D8,") when x""",DEC2HEX(Table!D8,2),"""",",") -> reg_q(5) when x"05",
A115: =CONCATENATE(" reg_q(",Table!D9,") when x""",DEC2HEX(Table!D9,2),"""",",") -> reg_q(6) when x"06",
A116: =CONCATENATE(" reg_q(",Table!D10,") when x""",DEC2HEX(Table!D10,2),"""",",") -> reg_q(7) when x"07",
A117: =CONCATENATE(" reg_q(",Table!D11,") when x""",DEC2HEX(Table!D11,2),"""",",") -> reg_q(8) when x"08",
A118: =CONCATENATE(" reg_q(",Table!D12,") when x""",DEC2HEX(Table!D12,2),"""",",") -> reg_q(9) when x"09",
A119: =CONCATENATE(" reg_q(",Table!D13,") when x""",DEC2HEX(Table!D13,2),"""",",") -> reg_q(10) when x"0A",
A120: =CONCATENATE(" reg_q(",Table!D14,") when x""",DEC2HEX(Table!D14,2),"""",",") -> reg_q(11) when x"0B",
... A214: =CONCATENATE(" reg_q(",Table!D108,") when x""",DEC2HEX(Table!D108,2),"""",",") -> reg_q(105) when x"69",
A216: x"FFFF" when others;

Sheet Register_Detail
A1: REG NUM | C1: NUM | D1: Description | E1: Bit # | F1: Bit Description | G1: Notes
A2: 0 | B2: VIP | C2: 1 | D2: Pump 1 Current Analog Readback | E2: 0-15 | F2: 16-Bit Analog Readback | G2: From HW
A3: 1 | B3: VIP | C3: 2 | D3: Pump 2 Current Analog Readback | E3: 0-15 | F3: 16-Bit Analog Readback | G3: From HW
A4: 2 | B4: VIP | C4: 3 | D4: Pump 3 Current Analog Readback | E4: 0-15 | F4: 16-Bit Analog Readback | G4: From HW
A5: 3 | B5: VIP | C5: 4 | D5: Pump 4 Current Analog Readback | E5: 0-15 | F5: 16-Bit Analog Readback | G5: From HW
A6: 4 | B6: VIP | C6: 5 | D6: Pump 5 Current Analog Readback | E6: 0-15 | F6: 16-Bit Analog Readback | G6: From HW
A7: 5 | B7: VIP | C7: 6 | D7: Pump 6 Current Analog Readback | E7: 0-15 | F7: 16-Bit Analog Readback | G7: From HW
A8: 6 | B8: VIP | C8: 7 | D8: Pump 7 Current Analog Readback | E8: 0-15 | F8: 16-Bit Analog Readback | G8: From HW
A9: 7 | B9: VIP | C9: 8 | D9: Pump 8 Current Analog Readback | E9: 0-15 | F9: 16-Bit Analog Readback | G9: From HW
A10: 8 | B10: VIP | C10: A | D10: Pump A Current Analog Readback | E10: 0-15 | F10: 16-Bit Analog Readback | G10: From HW
A11: 9 | B11: VIP | C11: B | D11: Pump B Current Analog Readback | E11: 0-15 | F11: 16-Bit Analog Readback | G11: From HW
A12: 10 | B12: VIP | C12: C | D12: Pump C Current Analog Readback | E12: 0-15 | F12: 16-Bit Analog Readback | G12: From HW
A13: 11 | B13: VIP | C13: V1 | D13: Pump 1 Voltage Analog Readback | E13: 0-15 | F13: 16-Bit Analog Readback | G13: From HW
A14: 12 | B14: VIP | C14: V2 | D14: Pump 2 Voltage Analog Readback | E14: 0-15 | F14: 16-Bit Analog Readback | G14: From HW
A15: 13 | B15: VIP | C15: V3 | D15: Pump 3 Voltage Analog Readback | E15: 0-15 | F15: 16-Bit Analog Readback | G15: From HW
A16: 14 | B16: VIP | C16: V4 | D16: Pump 4 Voltage Analog Readback | E16: 0-15 | F16: 16-Bit Analog Readback | G16: From HW
A17: 15 | B17: VIP | C17: V5 | D17: Pump 5 Voltage Analog Readback | E17: 0-15 | F17: 16-Bit Analog Readback | G17: From HW
A18: 16 | B18: VIP | C18: V6 | D18: Pump 6 Voltage Analog Readback | E18: 0-15 | F18: 16-Bit Analog Readback | G18: From HW
A19: 17 | B19: VIP | C19: V7 | D19: Pump 7 Voltage Analog Readback | E19: 0-15 | F19: 16-Bit Analog Readback | G19: From HW
A20: 18 | B20: VIP | C20: V8 | D20: Pump 8 Voltage Analog Readback | E20: 0-15 | F20: 16-Bit Analog Readback | G20: From HW
A21: 19 | B21: VIP | C21: VA | D21: Pump A Voltage Analog Readback | E21: 0-15 | F21: 16-Bit Analog Readback | G21: From HW
... A26: 24 | B26: VPG | C26: C | D26: Convectron C Analog Readback | E26: 0-15 | F26: 16-Bit Analog Readback | G26: From HW
A27: 25 | B27: VCG | D27: Cold Cathode Gauge Analog Readback | E27: 0-15 | F27: 16-Bit Analog Readback | G27: From HW
A28: 26 | B28: VQG | D28: Quattro Gauge Analog Readback | E28: 0-15 | F28: 16-Bit Analog Readback | G28: From HW
A29: 27 | B29: VPI | D29: Pressure Transducer Analog Readback | E29: 0-15 | F29: 16-Bit Analog Readback | G29: From HW
A30: 28 | B30: VAC | C30: ADC1 | D30: Spare ADC 1 Readback | E30: 0-15 | F30: 16-Bit Analog Readback | G30: From HW
A31: 29 | B31: VAC | C31: ADC2 | D31: Spare ADC 2 Readback | E31: 0-15 | F31: 16-Bit Analog Readback | G31: From HW
A32: 30 | B32: VAC | C32: ADC3 | D32: Spare ADC 3 Readback | E32: 0-15 | F32: 16-Bit Analog Readback | G32: From HW
A33: 31 | B33: VAC | C33: ADC4 | D33: Spare ADC 4 Readback | E33: 0-15 | F33: 16-Bit Analog Readback | G33: From HW
A34: 32 | B34: VIP | C34: LIM1 | D34: Pump 1 Slow Trip Limit | E34: 0-15 | F34: Signed 16-Bit Constant | G34: FW Setpoint
A35: 33 | B35: VIP | C35: LIM2 | D35: Pump 2 Slow Trip Limit | E35: 0-15 | F35: Signed 16-Bit Constant | G35: FW Setpoint
A36: 34 | B36: VIP | C36: LIM3 | D36: Pump 3 Slow Trip Limit | E36: 0-15 | F36: Signed 16-Bit Constant | G36: FW Setpoint
A37: 35 | B37: VIP | C37: LIM4 | D37: Pump 4 Slow Trip Limit | E37: 0-15 | F37: Signed 16-Bit Constant | G37: FW Setpoint
A38: 36 | B38: VIP | C38: LIM5 | D38: Pump 5 Slow Trip Limit | E38: 0-15 | F38: Signed 16-Bit Constant | G38: FW Setpoint
A39: 37 | B39: VIP | C39: LIM6 | D39: Pump 6 Slow Trip Limit | E39: 0-15 | F39: Signed 16-Bit Constant | G39: FW Setpoint
A40: 38 | B40: VIP | C40: LIM7 | D40: Pump 7 Slow Trip Limit | E40: 0-15 | F40: Signed 16-Bit Constant | G40: FW Setpoint
A41: 39 | B41: VIP | C41: LIM8 | D41: Pump 8 Slow Trip Limit | E41: 0-15 | F41: Signed 16-Bit Constant | G41: FW Setpoint
... A50: 48 | B50: VPI | C50: LIM | D50: Pressure Transducer Trip Limit | E50: 0-15 | F50: Signed 16-Bit Constant | G50: FW Setpoint
A51: 49 | B51: VIP | C51: HVEN | D51: Pump HV Enable Digital Control | E51: 0 | F51: Pump 1 HV Enable Digital Control | G51: HW Control Bit
E52: 1 | F52: Pump 2 HV Enable Digital Control | G52: HW Control Bit
...
